<?xml version="1.0" ?>
<robot name="ule_assembly" xmlns:xacro="http://www.ros.org/wiki/xacro">

<xacro:include filename="$(find ule_assembly_description)/urdf/materials.xacro" />
<xacro:include filename="$(find ule_assembly_description)/urdf/ule_assembly.trans" />
<xacro:include filename="$(find ule_assembly_description)/urdf/ule_assembly.gazebo" />

<link name="world"/>
<joint name="joint_base" type="fixed">
    <parent link="world"/>
    <child link="base_link"/>
</joint>

<link name="base_link">
  <inertial>
    <origin xyz="-0.022012879362131157 -0.019220083171915193 0.2816005117351987" rpy="0 0 0"/>
    <mass value="1.093144842042191"/>
    <inertia ixx="0.026076" iyy="0.024262" izz="0.006451" ixy="-0.001557" iyz="0.001307" ixz="0.001824"/>
  </inertial>
  <visual>
    <origin xyz="0 0 0" rpy="0 0 0"/>
    <geometry>
      <mesh filename="package://ule_assembly_description/meshes/base_link.stl" scale="0.001 0.001 0.001"/>
    </geometry>
    <material name="silver"/>
  </visual>
  <collision>
    <origin xyz="0 0 0" rpy="0 0 0"/>
    <geometry>
      <mesh filename="package://ule_assembly_description/meshes/base_link.stl" scale="0.001 0.001 0.001"/>
    </geometry>
  </collision>
</link>

<link name="Solid_2_v1_1">
  <inertial>
    <origin xyz="0.07694860321984921 -0.1578483785333 2.1017537927547902e-05" rpy="0 0 0"/>
    <mass value="0.25339650282694065"/>
    <inertia ixx="0.00097" iyy="0.000416" izz="0.001316" ixy="0.000458" iyz="0.0" ixz="-0.0"/>
  </inertial>
  <visual>
    <origin xyz="0.023592 0.100266 -0.352837" rpy="0 0 0"/>
    <geometry>
      <mesh filename="package://ule_assembly_description/meshes/Solid_2_v1_1.stl" scale="0.001 0.001 0.001"/>
    </geometry>
    <material name="silver"/>
  </visual>
  <collision>
    <origin xyz="0.023592 0.100266 -0.352837" rpy="0 0 0"/>
    <geometry>
      <mesh filename="package://ule_assembly_description/meshes/Solid_2_v1_1.stl" scale="0.001 0.001 0.001"/>
    </geometry>
  </collision>
</link>

<link name="Solid_3_v1_1">
  <inertial>
    <origin xyz="-2.0857283529948645e-05 -0.05269910669425781 -0.1932760159215091" rpy="0 0 0"/>
    <mass value="0.25465015328598006"/>
    <inertia ixx="0.001556" iyy="0.001124" izz="0.000503" ixy="-0.0" iyz="-0.000401" ixz="-0.0"/>
  </inertial>
  <visual>
    <origin xyz="-0.073378 0.203266 -0.352866" rpy="0 0 0"/>
    <geometry>
      <mesh filename="package://ule_assembly_description/meshes/Solid_3_v1_1.stl" scale="0.001 0.001 0.001"/>
    </geometry>
    <material name="silver"/>
  </visual>
  <collision>
    <origin xyz="-0.073378 0.203266 -0.352866" rpy="0 0 0"/>
    <geometry>
      <mesh filename="package://ule_assembly_description/meshes/Solid_3_v1_1.stl" scale="0.001 0.001 0.001"/>
    </geometry>
  </collision>
</link>

<link name="Solid_4_v1_1">
  <inertial>
    <origin xyz="0.2108236852870592 0.024189400464239508 -0.06364138139946746" rpy="0 0 0"/>
    <mass value="0.28213735045329447"/>
    <inertia ixx="0.000747" iyy="0.00215" izz="0.001565" ixy="-0.000223" iyz="0.000104" ixz="0.000652"/>
  </inertial>
  <visual>
    <origin xyz="-0.073349 0.191266 -0.127896" rpy="0 0 0"/>
    <geometry>
      <mesh filename="package://ule_assembly_description/meshes/Solid_4_v1_1.stl" scale="0.001 0.001 0.001"/>
    </geometry>
    <material name="silver"/>
  </visual>
  <collision>
    <origin xyz="-0.073349 0.191266 -0.127896" rpy="0 0 0"/>
    <geometry>
      <mesh filename="package://ule_assembly_description/meshes/Solid_4_v1_1.stl" scale="0.001 0.001 0.001"/>
    </geometry>
  </collision>
</link>

<link name="Solid_5_v1_1">
  <inertial>
    <origin xyz="0.07815512759409599 -5.687510059027012e-07 0.03039909226963544" rpy="0 0 0"/>
    <mass value="0.10205551496950795"/>
    <inertia ixx="0.000121" iyy="0.00018" izz="8.6e-05" ixy="-0.0" iyz="-0.0" ixz="-4e-05"/>
  </inertial>
  <visual>
    <origin xyz="-0.323349 0.161266 -0.119896" rpy="0 0 0"/>
    <geometry>
      <mesh filename="package://ule_assembly_description/meshes/Solid_5_v1_1.stl" scale="0.001 0.001 0.001"/>
    </geometry>
    <material name="silver"/>
  </visual>
  <collision>
    <origin xyz="-0.323349 0.161266 -0.119896" rpy="0 0 0"/>
    <geometry>
      <mesh filename="package://ule_assembly_description/meshes/Solid_5_v1_1.stl" scale="0.001 0.001 0.001"/>
    </geometry>
  </collision>
</link>

<joint name="Rev1" type="revolute">
  <origin xyz="-0.023592 -0.100266 0.352837" rpy="0 0 0"/>
  <parent link="base_link"/>
  <child link="Solid_2_v1_1"/>
  <axis xyz="1.0 0.0 0.0"/>
  <limit upper="0.0" lower="-1.22173" effort="100" velocity="100"/>
</joint>

<joint name="Rev2" type="revolute">
  <origin xyz="0.09697 -0.103 2.9e-05" rpy="0 0 0"/>
  <parent link="Solid_2_v1_1"/>
  <child link="Solid_3_v1_1"/>
  <axis xyz="-0.0 1.0 0.0"/>
  <limit upper="0.0" lower="-2.094395" effort="100" velocity="100"/>
</joint>

<joint name="Rev3" type="revolute">
  <origin xyz="-2.9e-05 0.012 -0.22497" rpy="0 0 0"/>
  <parent link="Solid_3_v1_1"/>
  <child link="Solid_4_v1_1"/>
  <axis xyz="-0.0 1.0 0.0"/>
  <limit upper="1.570796" lower="-0.698132" effort="100" velocity="100"/>
</joint>

<joint name="Rev4" type="revolute">
  <origin xyz="0.25 0.03 -0.008" rpy="0 0 0"/>
  <parent link="Solid_4_v1_1"/>
  <child link="Solid_5_v1_1"/>
  <axis xyz="-0.0 0.0 1.0"/>
  <limit upper="1.047198" lower="-1.134464" effort="100" velocity="100"/>
</joint>



</robot>
